<?xml version="1.0" ?>
<robot name="parallel_jaw">
	<link name="gripper_base">
		<inertial>
			<origin rpy="0.00000 -0.00000 0.00000" xyz="0.00000 0.00000 0.00000"/>
			<mass value="1.0"/>
			<inertia ixx="0.1" ixy="0" ixz="0" iyy="0.1" iyz="0" izz="0.1"/>
		</inertial>
		<visual>
			<origin rpy="0 0 0" xyz="0.00000 0.00000 0.00000"/>
			<geometry>
				<mesh filename="../assets/hand_meshes/gripper_base.obj" scale="1.00000 1.00000 1.00000"/>
			</geometry>
		</visual>
	</link>

	<link name="left_finger">
		<inertial>
			<origin rpy="0.00000 -0.00000 0.00000" xyz="0.00000 0.00000 0.00000"/>
			<mass value="0.1"/>
			<inertia ixx="0.1" ixy="0" ixz="0" iyy="0.1" iyz="0" izz="0.1"/>
		</inertial>
		<visual>
			<origin rpy="0.00000 0.00000 0.00000" xyz="0.00000 0.00000 0.00000"/>
			<geometry>
				<mesh filename="../assets/hand_meshes/left_finger.obj" scale="1.00000 1.00000 1.00000"/>
			</geometry>
		</visual>
	</link>

	<link name="right_finger">
		<inertial>
			<origin rpy="0.00000 0.00000 0.00000" xyz="0.00000 0.00000 0.00000"/>
			<mass value="0.00000"/>
			<inertia ixx="0.00000" ixy="0" ixz="0" iyy="0.00000" iyz="0" izz="0.00000"/>
		</inertial>
		<visual>
			<origin rpy="0.00000 0.00000 3.14159" xyz="0.00000 0.00000 0.00000"/>
			<geometry>
				<mesh filename="../assets/hand_meshes/right_finger.obj" scale="1.00000 1.00000 1.00000"/>
			</geometry>
		</visual>
	</link>
	<joint name="finger_joint1" type="prismatic">
		<parent link="gripper_base"/>
		<child link="left_finger"/>
		<limit effort="20.00000" lower="0.00000" upper="0.02550" velocity="1.00000"/>
		<dynamics damping="1.0" friction="0.0001"/>
		<origin rpy="0.00000 0.00000 0.00000" xyz="-0.02550 0.00000 0.00000"/>
		<axis xyz="1.00000 0.00000 0.00000"/>
	</joint>
	<joint name="finger_joint2" type="prismatic">
		<parent link="gripper_base"/>
		<child link="right_finger"/>
		<limit effort="20.00000" lower="0.00000" upper="0.02550" velocity="1.00000"/>
		<dynamics damping="1.0" friction="0.0001"/>
		<origin rpy="0.00000 0.00000 3.14159" xyz="0.02550 0.00000 0.00000"/>
		<axis xyz="1.00000 0.00000 0.00000"/>
	</joint>
</robot>
